[2023-07-08 18:38:19,119] {taskinstance.py:1032} INFO - Dependencies all met for <TaskInstance: Regions_ETL.cargar_data manual__2023-07-08T18:37:59.009049+00:00 [queued]>
[2023-07-08 18:38:19,203] {taskinstance.py:1032} INFO - Dependencies all met for <TaskInstance: Regions_ETL.cargar_data manual__2023-07-08T18:37:59.009049+00:00 [queued]>
[2023-07-08 18:38:19,234] {taskinstance.py:1238} INFO - 
--------------------------------------------------------------------------------
[2023-07-08 18:38:19,250] {taskinstance.py:1239} INFO - Starting attempt 1 of 6
[2023-07-08 18:38:19,252] {taskinstance.py:1240} INFO - 
--------------------------------------------------------------------------------
[2023-07-08 18:38:19,328] {taskinstance.py:1259} INFO - Executing <Task(PythonOperator): cargar_data> on 2023-07-08 18:37:59.009049+00:00
[2023-07-08 18:38:19,364] {standard_task_runner.py:52} INFO - Started process 494 to run task
[2023-07-08 18:38:19,398] {standard_task_runner.py:76} INFO - Running: ['***', 'tasks', 'run', 'Regions_ETL', 'cargar_data', 'manual__2023-07-08T18:37:59.009049+00:00', '--job-id', '17', '--raw', '--subdir', 'DAGS_FOLDER/ETL_Regions.py', '--cfg-path', '/tmp/tmpw7i2by86', '--error-file', '/tmp/tmpn9ufl9ai']
[2023-07-08 18:38:19,435] {standard_task_runner.py:77} INFO - Job 17: Subtask cargar_data
[2023-07-08 18:38:20,304] {logging_mixin.py:109} INFO - Running <TaskInstance: Regions_ETL.cargar_data manual__2023-07-08T18:37:59.009049+00:00 [running]> on host 3c75c5b6d9e6
[2023-07-08 18:38:20,760] {warnings.py:110} WARNING - /home/***/.local/lib/python3.7/site-packages/***/utils/context.py:152: AirflowContextDeprecationWarning: Accessing 'execution_date' from the template is deprecated and will be removed in a future version. Please use 'data_interval_start' or 'logical_date' instead.
  warnings.warn(_create_deprecation_warning(key, self._deprecation_replacements[key]))

[2023-07-08 18:38:21,007] {taskinstance.py:1426} INFO - Exporting the following env vars:
AIRFLOW_CTX_DAG_OWNER=gastonrios32
AIRFLOW_CTX_DAG_ID=Regions_ETL
AIRFLOW_CTX_TASK_ID=cargar_data
AIRFLOW_CTX_EXECUTION_DATE=2023-07-08T18:37:59.009049+00:00
AIRFLOW_CTX_DAG_RUN_ID=manual__2023-07-08T18:37:59.009049+00:00
[2023-07-08 18:38:21,085] {logging_mixin.py:109} INFO - Cargando la data para la fecha: 2023-07-08 18
[2023-07-08 18:38:21,465] {logging_mixin.py:109} INFO - (501, 9)
[2023-07-08 18:38:21,596] {logging_mixin.py:109} INFO -                        Name population  ...  timezones                    ETL_TIME
0                    Jordan   10203140  ...  UTC+03:00  2023-07-08 18:29:50.037340
1  Northern Mariana Islands      57557  ...  UTC+10:00  2023-07-08 18:29:50.037340
2                    Serbia    6908224  ...  UTC+01:00  2023-07-08 18:29:50.037340
3                   Andorra      77265  ...  UTC+01:00  2023-07-08 18:29:50.037340
4  Turks and Caicos Islands      38718  ...  UTC-04:00  2023-07-08 18:29:50.037340

[5 rows x 9 columns]
[2023-07-08 18:38:24,249] {taskinstance.py:1700} ERROR - Task failed with exception
Traceback (most recent call last):
  File "/home/airflow/.local/lib/python3.7/site-packages/airflow/models/taskinstance.py", line 1329, in _run_raw_task
    self._execute_task_with_callbacks(context)
  File "/home/airflow/.local/lib/python3.7/site-packages/airflow/models/taskinstance.py", line 1455, in _execute_task_with_callbacks
    result = self._execute_task(context, self.task)
  File "/home/airflow/.local/lib/python3.7/site-packages/airflow/models/taskinstance.py", line 1511, in _execute_task
    result = execute_callable(context=context)
  File "/home/airflow/.local/lib/python3.7/site-packages/airflow/operators/python.py", line 174, in execute
    return_value = self.execute_callable()
  File "/home/airflow/.local/lib/python3.7/site-packages/airflow/operators/python.py", line 185, in execute_callable
    return self.python_callable(*self.op_args, **self.op_kwargs)
  File "/opt/airflow/dags/ETL_Regions.py", line 159, in cargar_data
    execute_values(cur, insert_sql, values)
  File "/home/airflow/.local/lib/python3.7/site-packages/psycopg2/extras.py", line 1270, in execute_values
    cur.execute(b''.join(parts))
psycopg2.errors.InvalidTextRepresentation: invalid input syntax for integer: "population"

[2023-07-08 18:38:24,337] {taskinstance.py:1277} INFO - Marking task as UP_FOR_RETRY. dag_id=Regions_ETL, task_id=cargar_data, execution_date=20230708T183759, start_date=20230708T183819, end_date=20230708T183824
[2023-07-08 18:38:24,377] {standard_task_runner.py:92} ERROR - Failed to execute job 17 for task cargar_data
Traceback (most recent call last):
  File "/home/airflow/.local/lib/python3.7/site-packages/airflow/task/task_runner/standard_task_runner.py", line 85, in _start_by_fork
    args.func(args, dag=self.dag)
  File "/home/airflow/.local/lib/python3.7/site-packages/airflow/cli/cli_parser.py", line 48, in command
    return func(*args, **kwargs)
  File "/home/airflow/.local/lib/python3.7/site-packages/airflow/utils/cli.py", line 92, in wrapper
    return f(*args, **kwargs)
  File "/home/airflow/.local/lib/python3.7/site-packages/airflow/cli/commands/task_command.py", line 298, in task_run
    _run_task_by_selected_method(args, dag, ti)
  File "/home/airflow/.local/lib/python3.7/site-packages/airflow/cli/commands/task_command.py", line 107, in _run_task_by_selected_method
    _run_raw_task(args, ti)
  File "/home/airflow/.local/lib/python3.7/site-packages/airflow/cli/commands/task_command.py", line 184, in _run_raw_task
    error_file=args.error_file,
  File "/home/airflow/.local/lib/python3.7/site-packages/airflow/utils/session.py", line 70, in wrapper
    return func(*args, session=session, **kwargs)
  File "/home/airflow/.local/lib/python3.7/site-packages/airflow/models/taskinstance.py", line 1329, in _run_raw_task
    self._execute_task_with_callbacks(context)
  File "/home/airflow/.local/lib/python3.7/site-packages/airflow/models/taskinstance.py", line 1455, in _execute_task_with_callbacks
    result = self._execute_task(context, self.task)
  File "/home/airflow/.local/lib/python3.7/site-packages/airflow/models/taskinstance.py", line 1511, in _execute_task
    result = execute_callable(context=context)
  File "/home/airflow/.local/lib/python3.7/site-packages/airflow/operators/python.py", line 174, in execute
    return_value = self.execute_callable()
  File "/home/airflow/.local/lib/python3.7/site-packages/airflow/operators/python.py", line 185, in execute_callable
    return self.python_callable(*self.op_args, **self.op_kwargs)
  File "/opt/airflow/dags/ETL_Regions.py", line 159, in cargar_data
    execute_values(cur, insert_sql, values)
  File "/home/airflow/.local/lib/python3.7/site-packages/psycopg2/extras.py", line 1270, in execute_values
    cur.execute(b''.join(parts))
psycopg2.errors.InvalidTextRepresentation: invalid input syntax for integer: "population"

[2023-07-08 18:38:24,441] {local_task_job.py:154} INFO - Task exited with return code 1
[2023-07-08 18:38:24,637] {local_task_job.py:264} INFO - 0 downstream tasks scheduled from follow-on schedule check
